{
 "cells": [
  {
   "cell_type": "code",
   "execution_count": 1,
   "metadata": {},
   "outputs": [
    {
     "data": {
      "text/plain": [
       "[]"
      ]
     },
     "execution_count": 1,
     "metadata": {},
     "output_type": "execute_result"
    }
   ],
   "source": [
    "import tensorflow as tf\n",
    "tf.config.list_physical_devices('GPU')"
   ]
  },
  {
   "cell_type": "code",
   "execution_count": 2,
   "metadata": {},
   "outputs": [],
   "source": [
    "from tensorflow import keras\n",
    "import matplotlib.pyplot as plt\n",
    "import urllib3\n",
    "import numpy as np\n",
    "import os"
   ]
  },
  {
   "cell_type": "code",
   "execution_count": 3,
   "metadata": {},
   "outputs": [],
   "source": [
    "from keras.models import Model, Input\n",
    "from keras.layers import Conv2D, SeparableConv2D, Dense, MaxPooling2D, GlobalAveragePooling2D\n",
    "from keras.layers import Activation, BatchNormalization, Dropout\n",
    "from keras.layers import Add\n",
    "from keras.utils import to_categorical\n",
    "from keras.callbacks import Callback\n",
    "from keras.metrics import categorical_crossentropy\n",
    "from keras.optimizers import Adam\n",
    "from keras.optimizers import SGD\n",
    "from keras.regularizers import l2\n",
    "from keras.preprocessing import image\n",
    "from keras.preprocessing.image import ImageDataGenerator\n",
    "from sklearn.metrics import confusion_matrix\n",
    "\n",
    "import matplotlib.pyplot as plt\n",
    "import os\n",
    "import numpy as np\n",
    "import keras.backend as K"
   ]
  },
  {
   "cell_type": "code",
   "execution_count": 4,
   "metadata": {},
   "outputs": [],
   "source": [
    "def conv2d_bn(x, filters, kernel_size, padding='same', strides=1, activation='relu', weight_decay=1e-5):\n",
    "    x = Conv2D(filters, kernel_size, padding=padding, strides=strides, kernel_regularizer=l2(weight_decay))(x)\n",
    "    x = BatchNormalization()(x)\n",
    "    \n",
    "    if activation:\n",
    "        x = Activation(activation)(x)\n",
    "    \n",
    "    return x\n",
    "\n",
    "def sepconv2d_bn(x, filters, kernel_size, padding='same', strides=1, activation='relu', weight_decay=1e-5, depth_multiplier=1):\n",
    "    x = SeparableConv2D(filters, kernel_size, padding=padding, strides=strides, depth_multiplier=depth_multiplier, depthwise_regularizer=l2(weight_decay), pointwise_regularizer=l2(weight_decay))(x)\n",
    "    x = BatchNormalization()(x)\n",
    "    \n",
    "    if activation:\n",
    "        x = Activation(activation)(x)\n",
    "    \n",
    "    return x\n",
    "\n",
    "# def preprocess_input(x):\n",
    "#     return tf.keras.layers.experimental.preprocessing.Rescaling(scale=1./255)\n",
    "\n",
    "\n",
    "def Xception(model_input, classes):\n",
    "    ## input_data scaling\n",
    "    # x = preprocess_input(model_input)\n",
    "    \n",
    "    ## Entry flow\n",
    "    x = conv2d_bn(model_input, 32, (3, 3), strides=2) # (299, 299, 3) -> (150, 150, 32)\n",
    "    x = conv2d_bn(x, 64, (3, 3))\n",
    "\n",
    "    for fliters in [128, 256, 728]: # (75, 75, 64) -> (75, 75, 128) -> (38, 38, 256) -> (19, 19, 728)\n",
    "        residual = conv2d_bn(x, fliters, (1, 1), strides=2, activation=None)\n",
    "        \n",
    "        x = Activation(activation='relu')(x)\n",
    "        x = sepconv2d_bn(x, fliters, (3, 3))\n",
    "        x = sepconv2d_bn(x, fliters, (3, 3), activation=None)\n",
    "        x = MaxPooling2D((3, 3), padding='same', strides=2)(x)\n",
    "        \n",
    "        x = Add()([x, residual])\n",
    "        \n",
    "        \n",
    "    ## Middle flow\n",
    "    for i in range(8): # (19, 19, 728)\n",
    "        residual = x\n",
    "        \n",
    "        x = Activation(activation='relu')(x)\n",
    "        x = sepconv2d_bn(x, 728, (3, 3))\n",
    "        x = sepconv2d_bn(x, 728, (3, 3))\n",
    "        x = sepconv2d_bn(x, 728, (3, 3), activation=None)\n",
    "        \n",
    "        x = Add()([x, residual])\n",
    "        \n",
    "        \n",
    "    ## Exit flow\n",
    "    residual = conv2d_bn(x, 1024, (1, 1), strides=2, activation=None) # (19, 19, 728) -> (10, 10, 1024)\n",
    "        \n",
    "    x = Activation(activation='relu')(x)\n",
    "    x = sepconv2d_bn(x, 728, (3, 3))\n",
    "    x = sepconv2d_bn(x, 1024, (3, 3), activation=None) # (19, 19, 728) -> (19, 19, 1024)\n",
    "    x = MaxPooling2D((3, 3), padding='same', strides=2)(x) # (19, 19, 1024) -> (10, 10, 1024)\n",
    "    \n",
    "    x = Add()([x, residual])\n",
    "    \n",
    "    x = sepconv2d_bn(x, 1536, (3, 3))\n",
    "    x = sepconv2d_bn(x, 2048, (3, 3))\n",
    "\n",
    "    x = GlobalAveragePooling2D()(x)\n",
    "    \n",
    "    ## Optinal fully-connected layers\n",
    "    x = Dense(4096)(x)\n",
    "    x = BatchNormalization()(x)\n",
    "    x = Activation(activation='relu')(x)\n",
    "    \n",
    "#     x = Dense(4096)(x)\n",
    "#     x = BatchNormalization()(x)\n",
    "#     x = Activation(activation='relu')(x)\n",
    "    \n",
    "#     x = Dropout(0.4)(x)\n",
    "    \n",
    "    model_output = Dense(classes, activation='softmax')(x)\n",
    "    # model_output = Dense(classes, activation='sigmoid')(x)\n",
    "\n",
    "    model = Model(model_input, model_output, name='Xception')\n",
    "    \n",
    "    return model\n",
    "\n"
   ]
  },
  {
   "cell_type": "code",
   "execution_count": 5,
   "metadata": {},
   "outputs": [],
   "source": [
    "from tensorflow import keras\n",
    "model1 = keras.models.load_model('./models/xception_fake_well.h5')\n",
    "model2 = keras.models.load_model('./models/xception_real_well.h5')"
   ]
  },
  {
   "cell_type": "code",
   "execution_count": 6,
   "metadata": {},
   "outputs": [],
   "source": [
    "# labels = 'fake real'.split()\n",
    "# labels = np.array(labels)\n",
    "# labels\n",
    "\n",
    "\n",
    "# prediction = [[0, 1]]\n",
    "# # print({labels[i]: float(prediction[i]) for i in range(2)})\n",
    "# np.array(prediction).flatten().tolist()"
   ]
  },
  {
   "cell_type": "code",
   "execution_count": 7,
   "metadata": {
    "scrolled": false
   },
   "outputs": [
    {
     "name": "stdout",
     "output_type": "stream",
     "text": [
      "Running locally at: http://127.0.0.1:7860/\n",
      "To create a public link, set `share=True` in `launch()`.\n",
      "Interface loading below...\n"
     ]
    },
    {
     "data": {
      "text/html": [
       "\n",
       "        <iframe\n",
       "            width=\"900\"\n",
       "            height=\"500\"\n",
       "            src=\"http://127.0.0.1:7860/\"\n",
       "            frameborder=\"0\"\n",
       "            allowfullscreen\n",
       "        ></iframe>\n",
       "        "
      ],
      "text/plain": [
       "<IPython.lib.display.IFrame at 0x7f668c045f10>"
      ]
     },
     "metadata": {},
     "output_type": "display_data"
    },
    {
     "data": {
      "text/plain": [
       "(<Flask 'gradio.networking'>, 'http://127.0.0.1:7860/', None)"
      ]
     },
     "execution_count": 7,
     "metadata": {},
     "output_type": "execute_result"
    },
    {
     "name": "stdout",
     "output_type": "stream",
     "text": [
      "[0.4936301 0.5063699]\n",
      "[0.7503828  0.24961723]\n",
      "[0.65477014 0.34522983]\n",
      "[0.6657456  0.33425432]\n",
      "[0.4936301 0.5063699]\n",
      "[0.6657456  0.33425432]\n",
      "[0.88369596 0.11630408]\n",
      "[0.4936301 0.5063699]\n",
      "[0.65477014 0.34522983]\n",
      "[0.6657456  0.33425432]\n",
      "[0.88369596 0.11630408]\n"
     ]
    },
    {
     "name": "stderr",
     "output_type": "stream",
     "text": [
      "[2021-06-18 10:17:07,573] ERROR in app: Exception on /file/129_36.jpg [GET]\n",
      "Traceback (most recent call last):\n",
      "  File \"/home/ssac2/anaconda3/envs/aiffel/lib/python3.7/site-packages/flask/app.py\", line 2070, in wsgi_app\n",
      "    response = self.full_dispatch_request()\n",
      "  File \"/home/ssac2/anaconda3/envs/aiffel/lib/python3.7/site-packages/flask/app.py\", line 1515, in full_dispatch_request\n",
      "    rv = self.handle_user_exception(e)\n",
      "  File \"/home/ssac2/anaconda3/envs/aiffel/lib/python3.7/site-packages/flask_cors/extension.py\", line 165, in wrapped_function\n",
      "    return cors_after_request(app.make_response(f(*args, **kwargs)))\n",
      "  File \"/home/ssac2/anaconda3/envs/aiffel/lib/python3.7/site-packages/flask/app.py\", line 1513, in full_dispatch_request\n",
      "    rv = self.dispatch_request()\n",
      "  File \"/home/ssac2/anaconda3/envs/aiffel/lib/python3.7/site-packages/flask/app.py\", line 1499, in dispatch_request\n",
      "    return self.ensure_sync(self.view_functions[rule.endpoint])(**req.view_args)\n",
      "  File \"/home/ssac2/anaconda3/envs/aiffel/lib/python3.7/site-packages/gradio/networking.py\", line 89, in wrapper\n",
      "    return func(*args, **kwargs)\n",
      "  File \"/home/ssac2/anaconda3/envs/aiffel/lib/python3.7/site-packages/gradio/networking.py\", line 348, in file\n",
      "    return send_file(os.path.join(app.cwd, path))\n",
      "  File \"/home/ssac2/anaconda3/envs/aiffel/lib/python3.7/site-packages/flask/helpers.py\", line 625, in send_file\n",
      "    cache_timeout=cache_timeout,\n",
      "  File \"/home/ssac2/anaconda3/envs/aiffel/lib/python3.7/site-packages/werkzeug/utils.py\", line 697, in send_file\n",
      "    stat = os.stat(path)\n",
      "FileNotFoundError: [Errno 2] No such file or directory: '/home/ssac2/414vision/F.I.N.D./deepfake_detection/129_36.jpg'\n",
      "[2021-06-18 10:17:08,460] ERROR in app: Exception on /file/129_36.jpg [GET]\n",
      "Traceback (most recent call last):\n",
      "  File \"/home/ssac2/anaconda3/envs/aiffel/lib/python3.7/site-packages/flask/app.py\", line 2070, in wsgi_app\n",
      "    response = self.full_dispatch_request()\n",
      "  File \"/home/ssac2/anaconda3/envs/aiffel/lib/python3.7/site-packages/flask/app.py\", line 1515, in full_dispatch_request\n",
      "    rv = self.handle_user_exception(e)\n",
      "  File \"/home/ssac2/anaconda3/envs/aiffel/lib/python3.7/site-packages/flask_cors/extension.py\", line 165, in wrapped_function\n",
      "    return cors_after_request(app.make_response(f(*args, **kwargs)))\n",
      "  File \"/home/ssac2/anaconda3/envs/aiffel/lib/python3.7/site-packages/flask/app.py\", line 1513, in full_dispatch_request\n",
      "    rv = self.dispatch_request()\n",
      "  File \"/home/ssac2/anaconda3/envs/aiffel/lib/python3.7/site-packages/flask/app.py\", line 1499, in dispatch_request\n",
      "    return self.ensure_sync(self.view_functions[rule.endpoint])(**req.view_args)\n",
      "  File \"/home/ssac2/anaconda3/envs/aiffel/lib/python3.7/site-packages/gradio/networking.py\", line 89, in wrapper\n",
      "    return func(*args, **kwargs)\n",
      "  File \"/home/ssac2/anaconda3/envs/aiffel/lib/python3.7/site-packages/gradio/networking.py\", line 348, in file\n",
      "    return send_file(os.path.join(app.cwd, path))\n",
      "  File \"/home/ssac2/anaconda3/envs/aiffel/lib/python3.7/site-packages/flask/helpers.py\", line 625, in send_file\n",
      "    cache_timeout=cache_timeout,\n",
      "  File \"/home/ssac2/anaconda3/envs/aiffel/lib/python3.7/site-packages/werkzeug/utils.py\", line 697, in send_file\n",
      "    stat = os.stat(path)\n",
      "FileNotFoundError: [Errno 2] No such file or directory: '/home/ssac2/414vision/F.I.N.D./deepfake_detection/129_36.jpg'\n",
      "[2021-06-18 10:17:08,604] ERROR in app: Exception on /file/129_36.jpg [GET]\n",
      "Traceback (most recent call last):\n",
      "  File \"/home/ssac2/anaconda3/envs/aiffel/lib/python3.7/site-packages/flask/app.py\", line 2070, in wsgi_app\n",
      "    response = self.full_dispatch_request()\n",
      "  File \"/home/ssac2/anaconda3/envs/aiffel/lib/python3.7/site-packages/flask/app.py\", line 1515, in full_dispatch_request\n",
      "    rv = self.handle_user_exception(e)\n",
      "  File \"/home/ssac2/anaconda3/envs/aiffel/lib/python3.7/site-packages/flask_cors/extension.py\", line 165, in wrapped_function\n",
      "    return cors_after_request(app.make_response(f(*args, **kwargs)))\n",
      "  File \"/home/ssac2/anaconda3/envs/aiffel/lib/python3.7/site-packages/flask/app.py\", line 1513, in full_dispatch_request\n",
      "    rv = self.dispatch_request()\n",
      "  File \"/home/ssac2/anaconda3/envs/aiffel/lib/python3.7/site-packages/flask/app.py\", line 1499, in dispatch_request\n",
      "    return self.ensure_sync(self.view_functions[rule.endpoint])(**req.view_args)\n",
      "  File \"/home/ssac2/anaconda3/envs/aiffel/lib/python3.7/site-packages/gradio/networking.py\", line 89, in wrapper\n",
      "    return func(*args, **kwargs)\n",
      "  File \"/home/ssac2/anaconda3/envs/aiffel/lib/python3.7/site-packages/gradio/networking.py\", line 348, in file\n",
      "    return send_file(os.path.join(app.cwd, path))\n",
      "  File \"/home/ssac2/anaconda3/envs/aiffel/lib/python3.7/site-packages/flask/helpers.py\", line 625, in send_file\n",
      "    cache_timeout=cache_timeout,\n",
      "  File \"/home/ssac2/anaconda3/envs/aiffel/lib/python3.7/site-packages/werkzeug/utils.py\", line 697, in send_file\n",
      "    stat = os.stat(path)\n",
      "FileNotFoundError: [Errno 2] No such file or directory: '/home/ssac2/414vision/F.I.N.D./deepfake_detection/129_36.jpg'\n"
     ]
    },
    {
     "name": "stdout",
     "output_type": "stream",
     "text": [
      "[0.88369596 0.11630408]\n"
     ]
    },
    {
     "name": "stderr",
     "output_type": "stream",
     "text": [
      "[2021-06-18 10:17:10,117] ERROR in app: Exception on /file/129_36.jpg [GET]\n",
      "Traceback (most recent call last):\n",
      "  File \"/home/ssac2/anaconda3/envs/aiffel/lib/python3.7/site-packages/flask/app.py\", line 2070, in wsgi_app\n",
      "    response = self.full_dispatch_request()\n",
      "  File \"/home/ssac2/anaconda3/envs/aiffel/lib/python3.7/site-packages/flask/app.py\", line 1515, in full_dispatch_request\n",
      "    rv = self.handle_user_exception(e)\n",
      "  File \"/home/ssac2/anaconda3/envs/aiffel/lib/python3.7/site-packages/flask_cors/extension.py\", line 165, in wrapped_function\n",
      "    return cors_after_request(app.make_response(f(*args, **kwargs)))\n",
      "  File \"/home/ssac2/anaconda3/envs/aiffel/lib/python3.7/site-packages/flask/app.py\", line 1513, in full_dispatch_request\n",
      "    rv = self.dispatch_request()\n",
      "  File \"/home/ssac2/anaconda3/envs/aiffel/lib/python3.7/site-packages/flask/app.py\", line 1499, in dispatch_request\n",
      "    return self.ensure_sync(self.view_functions[rule.endpoint])(**req.view_args)\n",
      "  File \"/home/ssac2/anaconda3/envs/aiffel/lib/python3.7/site-packages/gradio/networking.py\", line 89, in wrapper\n",
      "    return func(*args, **kwargs)\n",
      "  File \"/home/ssac2/anaconda3/envs/aiffel/lib/python3.7/site-packages/gradio/networking.py\", line 348, in file\n",
      "    return send_file(os.path.join(app.cwd, path))\n",
      "  File \"/home/ssac2/anaconda3/envs/aiffel/lib/python3.7/site-packages/flask/helpers.py\", line 625, in send_file\n",
      "    cache_timeout=cache_timeout,\n",
      "  File \"/home/ssac2/anaconda3/envs/aiffel/lib/python3.7/site-packages/werkzeug/utils.py\", line 697, in send_file\n",
      "    stat = os.stat(path)\n",
      "FileNotFoundError: [Errno 2] No such file or directory: '/home/ssac2/414vision/F.I.N.D./deepfake_detection/129_36.jpg'\n",
      "[2021-06-18 10:17:10,430] ERROR in app: Exception on /file/129_36.jpg [GET]\n",
      "Traceback (most recent call last):\n",
      "  File \"/home/ssac2/anaconda3/envs/aiffel/lib/python3.7/site-packages/flask/app.py\", line 2070, in wsgi_app\n",
      "    response = self.full_dispatch_request()\n",
      "  File \"/home/ssac2/anaconda3/envs/aiffel/lib/python3.7/site-packages/flask/app.py\", line 1515, in full_dispatch_request\n",
      "    rv = self.handle_user_exception(e)\n",
      "  File \"/home/ssac2/anaconda3/envs/aiffel/lib/python3.7/site-packages/flask_cors/extension.py\", line 165, in wrapped_function\n",
      "    return cors_after_request(app.make_response(f(*args, **kwargs)))\n",
      "  File \"/home/ssac2/anaconda3/envs/aiffel/lib/python3.7/site-packages/flask/app.py\", line 1513, in full_dispatch_request\n",
      "    rv = self.dispatch_request()\n",
      "  File \"/home/ssac2/anaconda3/envs/aiffel/lib/python3.7/site-packages/flask/app.py\", line 1499, in dispatch_request\n",
      "    return self.ensure_sync(self.view_functions[rule.endpoint])(**req.view_args)\n",
      "  File \"/home/ssac2/anaconda3/envs/aiffel/lib/python3.7/site-packages/gradio/networking.py\", line 89, in wrapper\n",
      "    return func(*args, **kwargs)\n",
      "  File \"/home/ssac2/anaconda3/envs/aiffel/lib/python3.7/site-packages/gradio/networking.py\", line 348, in file\n",
      "    return send_file(os.path.join(app.cwd, path))\n",
      "  File \"/home/ssac2/anaconda3/envs/aiffel/lib/python3.7/site-packages/flask/helpers.py\", line 625, in send_file\n",
      "    cache_timeout=cache_timeout,\n",
      "  File \"/home/ssac2/anaconda3/envs/aiffel/lib/python3.7/site-packages/werkzeug/utils.py\", line 697, in send_file\n",
      "    stat = os.stat(path)\n",
      "FileNotFoundError: [Errno 2] No such file or directory: '/home/ssac2/414vision/F.I.N.D./deepfake_detection/129_36.jpg'\n",
      "[2021-06-18 10:17:10,572] ERROR in app: Exception on /file/129_36.jpg [GET]\n",
      "Traceback (most recent call last):\n",
      "  File \"/home/ssac2/anaconda3/envs/aiffel/lib/python3.7/site-packages/flask/app.py\", line 2070, in wsgi_app\n",
      "    response = self.full_dispatch_request()\n",
      "  File \"/home/ssac2/anaconda3/envs/aiffel/lib/python3.7/site-packages/flask/app.py\", line 1515, in full_dispatch_request\n",
      "    rv = self.handle_user_exception(e)\n",
      "  File \"/home/ssac2/anaconda3/envs/aiffel/lib/python3.7/site-packages/flask_cors/extension.py\", line 165, in wrapped_function\n",
      "    return cors_after_request(app.make_response(f(*args, **kwargs)))\n",
      "  File \"/home/ssac2/anaconda3/envs/aiffel/lib/python3.7/site-packages/flask/app.py\", line 1513, in full_dispatch_request\n",
      "    rv = self.dispatch_request()\n",
      "  File \"/home/ssac2/anaconda3/envs/aiffel/lib/python3.7/site-packages/flask/app.py\", line 1499, in dispatch_request\n",
      "    return self.ensure_sync(self.view_functions[rule.endpoint])(**req.view_args)\n",
      "  File \"/home/ssac2/anaconda3/envs/aiffel/lib/python3.7/site-packages/gradio/networking.py\", line 89, in wrapper\n",
      "    return func(*args, **kwargs)\n",
      "  File \"/home/ssac2/anaconda3/envs/aiffel/lib/python3.7/site-packages/gradio/networking.py\", line 348, in file\n",
      "    return send_file(os.path.join(app.cwd, path))\n",
      "  File \"/home/ssac2/anaconda3/envs/aiffel/lib/python3.7/site-packages/flask/helpers.py\", line 625, in send_file\n",
      "    cache_timeout=cache_timeout,\n",
      "  File \"/home/ssac2/anaconda3/envs/aiffel/lib/python3.7/site-packages/werkzeug/utils.py\", line 697, in send_file\n",
      "    stat = os.stat(path)\n",
      "FileNotFoundError: [Errno 2] No such file or directory: '/home/ssac2/414vision/F.I.N.D./deepfake_detection/129_36.jpg'\n",
      "[2021-06-18 10:17:10,715] ERROR in app: Exception on /file/129_36.jpg [GET]\n",
      "Traceback (most recent call last):\n",
      "  File \"/home/ssac2/anaconda3/envs/aiffel/lib/python3.7/site-packages/flask/app.py\", line 2070, in wsgi_app\n",
      "    response = self.full_dispatch_request()\n",
      "  File \"/home/ssac2/anaconda3/envs/aiffel/lib/python3.7/site-packages/flask/app.py\", line 1515, in full_dispatch_request\n",
      "    rv = self.handle_user_exception(e)\n",
      "  File \"/home/ssac2/anaconda3/envs/aiffel/lib/python3.7/site-packages/flask_cors/extension.py\", line 165, in wrapped_function\n",
      "    return cors_after_request(app.make_response(f(*args, **kwargs)))\n",
      "  File \"/home/ssac2/anaconda3/envs/aiffel/lib/python3.7/site-packages/flask/app.py\", line 1513, in full_dispatch_request\n",
      "    rv = self.dispatch_request()\n",
      "  File \"/home/ssac2/anaconda3/envs/aiffel/lib/python3.7/site-packages/flask/app.py\", line 1499, in dispatch_request\n",
      "    return self.ensure_sync(self.view_functions[rule.endpoint])(**req.view_args)\n",
      "  File \"/home/ssac2/anaconda3/envs/aiffel/lib/python3.7/site-packages/gradio/networking.py\", line 89, in wrapper\n",
      "    return func(*args, **kwargs)\n",
      "  File \"/home/ssac2/anaconda3/envs/aiffel/lib/python3.7/site-packages/gradio/networking.py\", line 348, in file\n",
      "    return send_file(os.path.join(app.cwd, path))\n",
      "  File \"/home/ssac2/anaconda3/envs/aiffel/lib/python3.7/site-packages/flask/helpers.py\", line 625, in send_file\n",
      "    cache_timeout=cache_timeout,\n",
      "  File \"/home/ssac2/anaconda3/envs/aiffel/lib/python3.7/site-packages/werkzeug/utils.py\", line 697, in send_file\n",
      "    stat = os.stat(path)\n",
      "FileNotFoundError: [Errno 2] No such file or directory: '/home/ssac2/414vision/F.I.N.D./deepfake_detection/129_36.jpg'\n",
      "[2021-06-18 10:17:10,837] ERROR in app: Exception on /file/129_36.jpg [GET]\n",
      "Traceback (most recent call last):\n",
      "  File \"/home/ssac2/anaconda3/envs/aiffel/lib/python3.7/site-packages/flask/app.py\", line 2070, in wsgi_app\n",
      "    response = self.full_dispatch_request()\n",
      "  File \"/home/ssac2/anaconda3/envs/aiffel/lib/python3.7/site-packages/flask/app.py\", line 1515, in full_dispatch_request\n",
      "    rv = self.handle_user_exception(e)\n",
      "  File \"/home/ssac2/anaconda3/envs/aiffel/lib/python3.7/site-packages/flask_cors/extension.py\", line 165, in wrapped_function\n",
      "    return cors_after_request(app.make_response(f(*args, **kwargs)))\n",
      "  File \"/home/ssac2/anaconda3/envs/aiffel/lib/python3.7/site-packages/flask/app.py\", line 1513, in full_dispatch_request\n",
      "    rv = self.dispatch_request()\n",
      "  File \"/home/ssac2/anaconda3/envs/aiffel/lib/python3.7/site-packages/flask/app.py\", line 1499, in dispatch_request\n",
      "    return self.ensure_sync(self.view_functions[rule.endpoint])(**req.view_args)\n",
      "  File \"/home/ssac2/anaconda3/envs/aiffel/lib/python3.7/site-packages/gradio/networking.py\", line 89, in wrapper\n",
      "    return func(*args, **kwargs)\n",
      "  File \"/home/ssac2/anaconda3/envs/aiffel/lib/python3.7/site-packages/gradio/networking.py\", line 348, in file\n",
      "    return send_file(os.path.join(app.cwd, path))\n",
      "  File \"/home/ssac2/anaconda3/envs/aiffel/lib/python3.7/site-packages/flask/helpers.py\", line 625, in send_file\n",
      "    cache_timeout=cache_timeout,\n",
      "  File \"/home/ssac2/anaconda3/envs/aiffel/lib/python3.7/site-packages/werkzeug/utils.py\", line 697, in send_file\n",
      "    stat = os.stat(path)\n",
      "FileNotFoundError: [Errno 2] No such file or directory: '/home/ssac2/414vision/F.I.N.D./deepfake_detection/129_36.jpg'\n"
     ]
    },
    {
     "name": "stderr",
     "output_type": "stream",
     "text": [
      "[2021-06-18 10:17:11,413] ERROR in app: Exception on /file/145_470.jpg [GET]\n",
      "Traceback (most recent call last):\n",
      "  File \"/home/ssac2/anaconda3/envs/aiffel/lib/python3.7/site-packages/flask/app.py\", line 2070, in wsgi_app\n",
      "    response = self.full_dispatch_request()\n",
      "  File \"/home/ssac2/anaconda3/envs/aiffel/lib/python3.7/site-packages/flask/app.py\", line 1515, in full_dispatch_request\n",
      "    rv = self.handle_user_exception(e)\n",
      "  File \"/home/ssac2/anaconda3/envs/aiffel/lib/python3.7/site-packages/flask_cors/extension.py\", line 165, in wrapped_function\n",
      "    return cors_after_request(app.make_response(f(*args, **kwargs)))\n",
      "  File \"/home/ssac2/anaconda3/envs/aiffel/lib/python3.7/site-packages/flask/app.py\", line 1513, in full_dispatch_request\n",
      "    rv = self.dispatch_request()\n",
      "  File \"/home/ssac2/anaconda3/envs/aiffel/lib/python3.7/site-packages/flask/app.py\", line 1499, in dispatch_request\n",
      "    return self.ensure_sync(self.view_functions[rule.endpoint])(**req.view_args)\n",
      "  File \"/home/ssac2/anaconda3/envs/aiffel/lib/python3.7/site-packages/gradio/networking.py\", line 89, in wrapper\n",
      "    return func(*args, **kwargs)\n",
      "  File \"/home/ssac2/anaconda3/envs/aiffel/lib/python3.7/site-packages/gradio/networking.py\", line 348, in file\n",
      "    return send_file(os.path.join(app.cwd, path))\n",
      "  File \"/home/ssac2/anaconda3/envs/aiffel/lib/python3.7/site-packages/flask/helpers.py\", line 625, in send_file\n",
      "    cache_timeout=cache_timeout,\n",
      "  File \"/home/ssac2/anaconda3/envs/aiffel/lib/python3.7/site-packages/werkzeug/utils.py\", line 697, in send_file\n",
      "    stat = os.stat(path)\n",
      "FileNotFoundError: [Errno 2] No such file or directory: '/home/ssac2/414vision/F.I.N.D./deepfake_detection/145_470.jpg'\n",
      "[2021-06-18 10:17:11,729] ERROR in app: Exception on /file/157_18.jpg [GET]\n",
      "Traceback (most recent call last):\n",
      "  File \"/home/ssac2/anaconda3/envs/aiffel/lib/python3.7/site-packages/flask/app.py\", line 2070, in wsgi_app\n",
      "    response = self.full_dispatch_request()\n",
      "  File \"/home/ssac2/anaconda3/envs/aiffel/lib/python3.7/site-packages/flask/app.py\", line 1515, in full_dispatch_request\n",
      "    rv = self.handle_user_exception(e)\n",
      "  File \"/home/ssac2/anaconda3/envs/aiffel/lib/python3.7/site-packages/flask_cors/extension.py\", line 165, in wrapped_function\n",
      "    return cors_after_request(app.make_response(f(*args, **kwargs)))\n",
      "  File \"/home/ssac2/anaconda3/envs/aiffel/lib/python3.7/site-packages/flask/app.py\", line 1513, in full_dispatch_request\n",
      "    rv = self.dispatch_request()\n",
      "  File \"/home/ssac2/anaconda3/envs/aiffel/lib/python3.7/site-packages/flask/app.py\", line 1499, in dispatch_request\n",
      "    return self.ensure_sync(self.view_functions[rule.endpoint])(**req.view_args)\n",
      "  File \"/home/ssac2/anaconda3/envs/aiffel/lib/python3.7/site-packages/gradio/networking.py\", line 89, in wrapper\n",
      "    return func(*args, **kwargs)\n",
      "  File \"/home/ssac2/anaconda3/envs/aiffel/lib/python3.7/site-packages/gradio/networking.py\", line 348, in file\n",
      "    return send_file(os.path.join(app.cwd, path))\n",
      "  File \"/home/ssac2/anaconda3/envs/aiffel/lib/python3.7/site-packages/flask/helpers.py\", line 625, in send_file\n",
      "    cache_timeout=cache_timeout,\n",
      "  File \"/home/ssac2/anaconda3/envs/aiffel/lib/python3.7/site-packages/werkzeug/utils.py\", line 697, in send_file\n",
      "    stat = os.stat(path)\n",
      "FileNotFoundError: [Errno 2] No such file or directory: '/home/ssac2/414vision/F.I.N.D./deepfake_detection/157_18.jpg'\n",
      "[2021-06-18 10:17:12,408] ERROR in app: Exception on /file/157_18.jpg [GET]\n",
      "Traceback (most recent call last):\n",
      "  File \"/home/ssac2/anaconda3/envs/aiffel/lib/python3.7/site-packages/flask/app.py\", line 2070, in wsgi_app\n",
      "    response = self.full_dispatch_request()\n",
      "  File \"/home/ssac2/anaconda3/envs/aiffel/lib/python3.7/site-packages/flask/app.py\", line 1515, in full_dispatch_request\n",
      "    rv = self.handle_user_exception(e)\n",
      "  File \"/home/ssac2/anaconda3/envs/aiffel/lib/python3.7/site-packages/flask_cors/extension.py\", line 165, in wrapped_function\n",
      "    return cors_after_request(app.make_response(f(*args, **kwargs)))\n",
      "  File \"/home/ssac2/anaconda3/envs/aiffel/lib/python3.7/site-packages/flask/app.py\", line 1513, in full_dispatch_request\n",
      "    rv = self.dispatch_request()\n",
      "  File \"/home/ssac2/anaconda3/envs/aiffel/lib/python3.7/site-packages/flask/app.py\", line 1499, in dispatch_request\n",
      "    return self.ensure_sync(self.view_functions[rule.endpoint])(**req.view_args)\n",
      "  File \"/home/ssac2/anaconda3/envs/aiffel/lib/python3.7/site-packages/gradio/networking.py\", line 89, in wrapper\n",
      "    return func(*args, **kwargs)\n",
      "  File \"/home/ssac2/anaconda3/envs/aiffel/lib/python3.7/site-packages/gradio/networking.py\", line 348, in file\n",
      "    return send_file(os.path.join(app.cwd, path))\n",
      "  File \"/home/ssac2/anaconda3/envs/aiffel/lib/python3.7/site-packages/flask/helpers.py\", line 625, in send_file\n",
      "    cache_timeout=cache_timeout,\n",
      "  File \"/home/ssac2/anaconda3/envs/aiffel/lib/python3.7/site-packages/werkzeug/utils.py\", line 697, in send_file\n",
      "    stat = os.stat(path)\n",
      "FileNotFoundError: [Errno 2] No such file or directory: '/home/ssac2/414vision/F.I.N.D./deepfake_detection/157_18.jpg'\n",
      "[2021-06-18 10:17:12,838] ERROR in app: Exception on /file/176_150.jpg [GET]\n",
      "Traceback (most recent call last):\n",
      "  File \"/home/ssac2/anaconda3/envs/aiffel/lib/python3.7/site-packages/flask/app.py\", line 2070, in wsgi_app\n",
      "    response = self.full_dispatch_request()\n",
      "  File \"/home/ssac2/anaconda3/envs/aiffel/lib/python3.7/site-packages/flask/app.py\", line 1515, in full_dispatch_request\n",
      "    rv = self.handle_user_exception(e)\n",
      "  File \"/home/ssac2/anaconda3/envs/aiffel/lib/python3.7/site-packages/flask_cors/extension.py\", line 165, in wrapped_function\n",
      "    return cors_after_request(app.make_response(f(*args, **kwargs)))\n",
      "  File \"/home/ssac2/anaconda3/envs/aiffel/lib/python3.7/site-packages/flask/app.py\", line 1513, in full_dispatch_request\n",
      "    rv = self.dispatch_request()\n",
      "  File \"/home/ssac2/anaconda3/envs/aiffel/lib/python3.7/site-packages/flask/app.py\", line 1499, in dispatch_request\n",
      "    return self.ensure_sync(self.view_functions[rule.endpoint])(**req.view_args)\n",
      "  File \"/home/ssac2/anaconda3/envs/aiffel/lib/python3.7/site-packages/gradio/networking.py\", line 89, in wrapper\n",
      "    return func(*args, **kwargs)\n",
      "  File \"/home/ssac2/anaconda3/envs/aiffel/lib/python3.7/site-packages/gradio/networking.py\", line 348, in file\n",
      "    return send_file(os.path.join(app.cwd, path))\n",
      "  File \"/home/ssac2/anaconda3/envs/aiffel/lib/python3.7/site-packages/flask/helpers.py\", line 625, in send_file\n",
      "    cache_timeout=cache_timeout,\n",
      "  File \"/home/ssac2/anaconda3/envs/aiffel/lib/python3.7/site-packages/werkzeug/utils.py\", line 697, in send_file\n",
      "    stat = os.stat(path)\n",
      "FileNotFoundError: [Errno 2] No such file or directory: '/home/ssac2/414vision/F.I.N.D./deepfake_detection/176_150.jpg'\n",
      "[2021-06-18 10:17:13,806] ERROR in app: Exception on /file/179_180.jpg [GET]\n",
      "Traceback (most recent call last):\n",
      "  File \"/home/ssac2/anaconda3/envs/aiffel/lib/python3.7/site-packages/flask/app.py\", line 2070, in wsgi_app\n",
      "    response = self.full_dispatch_request()\n",
      "  File \"/home/ssac2/anaconda3/envs/aiffel/lib/python3.7/site-packages/flask/app.py\", line 1515, in full_dispatch_request\n",
      "    rv = self.handle_user_exception(e)\n",
      "  File \"/home/ssac2/anaconda3/envs/aiffel/lib/python3.7/site-packages/flask_cors/extension.py\", line 165, in wrapped_function\n",
      "    return cors_after_request(app.make_response(f(*args, **kwargs)))\n",
      "  File \"/home/ssac2/anaconda3/envs/aiffel/lib/python3.7/site-packages/flask/app.py\", line 1513, in full_dispatch_request\n",
      "    rv = self.dispatch_request()\n",
      "  File \"/home/ssac2/anaconda3/envs/aiffel/lib/python3.7/site-packages/flask/app.py\", line 1499, in dispatch_request\n",
      "    return self.ensure_sync(self.view_functions[rule.endpoint])(**req.view_args)\n",
      "  File \"/home/ssac2/anaconda3/envs/aiffel/lib/python3.7/site-packages/gradio/networking.py\", line 89, in wrapper\n",
      "    return func(*args, **kwargs)\n",
      "  File \"/home/ssac2/anaconda3/envs/aiffel/lib/python3.7/site-packages/gradio/networking.py\", line 348, in file\n",
      "    return send_file(os.path.join(app.cwd, path))\n",
      "  File \"/home/ssac2/anaconda3/envs/aiffel/lib/python3.7/site-packages/flask/helpers.py\", line 625, in send_file\n",
      "    cache_timeout=cache_timeout,\n",
      "  File \"/home/ssac2/anaconda3/envs/aiffel/lib/python3.7/site-packages/werkzeug/utils.py\", line 697, in send_file\n",
      "    stat = os.stat(path)\n",
      "FileNotFoundError: [Errno 2] No such file or directory: '/home/ssac2/414vision/F.I.N.D./deepfake_detection/179_180.jpg'\n"
     ]
    },
    {
     "name": "stderr",
     "output_type": "stream",
     "text": [
      "[2021-06-18 10:17:13,897] ERROR in app: Exception on /file/179_180.jpg [GET]\n",
      "Traceback (most recent call last):\n",
      "  File \"/home/ssac2/anaconda3/envs/aiffel/lib/python3.7/site-packages/flask/app.py\", line 2070, in wsgi_app\n",
      "    response = self.full_dispatch_request()\n",
      "  File \"/home/ssac2/anaconda3/envs/aiffel/lib/python3.7/site-packages/flask/app.py\", line 1515, in full_dispatch_request\n",
      "    rv = self.handle_user_exception(e)\n",
      "  File \"/home/ssac2/anaconda3/envs/aiffel/lib/python3.7/site-packages/flask_cors/extension.py\", line 165, in wrapped_function\n",
      "    return cors_after_request(app.make_response(f(*args, **kwargs)))\n",
      "  File \"/home/ssac2/anaconda3/envs/aiffel/lib/python3.7/site-packages/flask/app.py\", line 1513, in full_dispatch_request\n",
      "    rv = self.dispatch_request()\n",
      "  File \"/home/ssac2/anaconda3/envs/aiffel/lib/python3.7/site-packages/flask/app.py\", line 1499, in dispatch_request\n",
      "    return self.ensure_sync(self.view_functions[rule.endpoint])(**req.view_args)\n",
      "  File \"/home/ssac2/anaconda3/envs/aiffel/lib/python3.7/site-packages/gradio/networking.py\", line 89, in wrapper\n",
      "    return func(*args, **kwargs)\n",
      "  File \"/home/ssac2/anaconda3/envs/aiffel/lib/python3.7/site-packages/gradio/networking.py\", line 348, in file\n",
      "    return send_file(os.path.join(app.cwd, path))\n",
      "  File \"/home/ssac2/anaconda3/envs/aiffel/lib/python3.7/site-packages/flask/helpers.py\", line 625, in send_file\n",
      "    cache_timeout=cache_timeout,\n",
      "  File \"/home/ssac2/anaconda3/envs/aiffel/lib/python3.7/site-packages/werkzeug/utils.py\", line 697, in send_file\n",
      "    stat = os.stat(path)\n",
      "FileNotFoundError: [Errno 2] No such file or directory: '/home/ssac2/414vision/F.I.N.D./deepfake_detection/179_180.jpg'\n",
      "[2021-06-18 10:17:14,123] ERROR in app: Exception on /file/179_180.jpg [GET]\n",
      "Traceback (most recent call last):\n",
      "  File \"/home/ssac2/anaconda3/envs/aiffel/lib/python3.7/site-packages/flask/app.py\", line 2070, in wsgi_app\n",
      "    response = self.full_dispatch_request()\n",
      "  File \"/home/ssac2/anaconda3/envs/aiffel/lib/python3.7/site-packages/flask/app.py\", line 1515, in full_dispatch_request\n",
      "    rv = self.handle_user_exception(e)\n",
      "  File \"/home/ssac2/anaconda3/envs/aiffel/lib/python3.7/site-packages/flask_cors/extension.py\", line 165, in wrapped_function\n",
      "    return cors_after_request(app.make_response(f(*args, **kwargs)))\n",
      "  File \"/home/ssac2/anaconda3/envs/aiffel/lib/python3.7/site-packages/flask/app.py\", line 1513, in full_dispatch_request\n",
      "    rv = self.dispatch_request()\n",
      "  File \"/home/ssac2/anaconda3/envs/aiffel/lib/python3.7/site-packages/flask/app.py\", line 1499, in dispatch_request\n",
      "    return self.ensure_sync(self.view_functions[rule.endpoint])(**req.view_args)\n",
      "  File \"/home/ssac2/anaconda3/envs/aiffel/lib/python3.7/site-packages/gradio/networking.py\", line 89, in wrapper\n",
      "    return func(*args, **kwargs)\n",
      "  File \"/home/ssac2/anaconda3/envs/aiffel/lib/python3.7/site-packages/gradio/networking.py\", line 348, in file\n",
      "    return send_file(os.path.join(app.cwd, path))\n",
      "  File \"/home/ssac2/anaconda3/envs/aiffel/lib/python3.7/site-packages/flask/helpers.py\", line 625, in send_file\n",
      "    cache_timeout=cache_timeout,\n",
      "  File \"/home/ssac2/anaconda3/envs/aiffel/lib/python3.7/site-packages/werkzeug/utils.py\", line 697, in send_file\n",
      "    stat = os.stat(path)\n",
      "FileNotFoundError: [Errno 2] No such file or directory: '/home/ssac2/414vision/F.I.N.D./deepfake_detection/179_180.jpg'\n"
     ]
    }
   ],
   "source": [
    "import gradio as gr\n",
    "from PIL import Image\n",
    "\n",
    "labels = 'fake real'.split()\n",
    "\n",
    "def classify_image(inp):\n",
    "    inp = inp.reshape((-1, 299, 299, 3))\n",
    "    # inp = tf.keras.applications.xception.preprocess_input(inp)\n",
    "    \n",
    "    pred_fake_well = model1.predict(inp)\n",
    "    pred_fake_well = np.array(pred_fake_well).flatten() # .tolist()\n",
    "    pred_real_well = model2.predict(inp)\n",
    "    pred_real_well = np.array(pred_real_well).flatten() # .tolist()\n",
    "\n",
    "    # print(pred_fake_well)\n",
    "    # print(pred_real_well)\n",
    "    prediction = pred_fake_well*0.5 + pred_real_well*0.5\n",
    "    \n",
    "    # prediction = [pred_fake_well[i] + pred_real_well[i] for i in range(len(pred_fake_well))]\n",
    "    # prediction = [prediction[i] * 0.5 for i in range(len(prediction))]\n",
    "    print(prediction)\n",
    "    # return 'Fake' if prediction[0][0] > prediction[0][1] else 'Real'\n",
    "    # return 'Fake : %f' %(prediction[0][0] * 100)\n",
    "    \n",
    "#     real_stamp = Image.open('real.JPG')\n",
    "#     fake_stamp = Image.open('fake.JPG')\n",
    "    \n",
    "    if np.argmax(prediction) == 1:\n",
    "#         plt.imshow(real_stamp)\n",
    "#         plt.show()\n",
    "        stamp = Image.open('real_stamp.png')\n",
    "    else:\n",
    "#         plt.imshow(fake_stamp)\n",
    "#         plt.show()\n",
    "        stamp = Image.open('fake_stamp.png')\n",
    "    \n",
    "    # plt.cla()\n",
    "    return {labels[i]: float(prediction[i]) for i in range(2)}, np.array(stamp)\n",
    "    \n",
    "\n",
    "image = gr.inputs.Image(shape=(299, 299))\n",
    "label = gr.outputs.Label(num_top_classes=2)\n",
    "'''\n",
    "sample_images = [\n",
    "                    [\"129_36.jpg\"],\n",
    "                    [\"145_470.jpg\"],\n",
    "                    [\"157_18.jpg\"],\n",
    "                    [\"176_150.jpg\"],\n",
    "                    [\"179_180.jpg\"],\n",
    "]\n",
    "'''\n",
    "\n",
    "\n",
    "gr.Interface(# fn=[classify_image, classify_stamp],\n",
    "             fn = classify_image,\n",
    "             inputs=image, \n",
    "             # outputs=label,\n",
    "             outputs = [gr.outputs.Label(num_top_classes=2), \"image\"],\n",
    "             capture_session=True, \n",
    "             title=\"Real or Fake ?\",\n",
    "             # examples=sample_images\n",
    "            ).launch()"
   ]
  },
  {
   "cell_type": "code",
   "execution_count": null,
   "metadata": {},
   "outputs": [],
   "source": []
  }
 ],
 "metadata": {
  "colab": {
   "authorship_tag": "ABX9TyMGf12RBU/NQW90ixyCTFIx",
   "collapsed_sections": [],
   "name": "Gradio Interface code.ipynb",
   "private_outputs": true,
   "provenance": []
  },
  "kernelspec": {
   "display_name": "aiffel",
   "language": "python",
   "name": "aiffel"
  },
  "language_info": {
   "codemirror_mode": {
    "name": "ipython",
    "version": 3
   },
   "file_extension": ".py",
   "mimetype": "text/x-python",
   "name": "python",
   "nbconvert_exporter": "python",
   "pygments_lexer": "ipython3",
   "version": "3.7.10"
  }
 },
 "nbformat": 4,
 "nbformat_minor": 1
}
